Workbook

Sheet 連結TOC
A1: 分類 | B1: 名稱 | C1: 路徑/位置 | D1: 狀態/說明 | E1: 連結
A2: ① Excel 總庫 4 檔
A3: 重建版 | B3: 台灣22縣市重劃區_全站資料庫_重建分類版.xlsx | C3: (本檔) | D3: 8 sheets
A4: └ sheet | B4: 連結TOC | C4: #連結TOC!A1 | D4: 本檔內部連結 | E4: #連結TOC!A1
A5: └ sheet | B5: 主庫_重劃區146區 | C5: #主庫_重劃區146區!A1 | D5: 本檔內部連結 | E5: #主庫_重劃區146區!A1
A6: └ sheet | B6: 建案總表_642案 | C6: #建案總表_642案!A1 | D6: 本檔內部連結 | E6: #建案總表_642案!A1
A7: └ sheet | B7: 重劃區清單_含內頁連結 | C7: #重劃區清單_含內頁連結!A1 | D7: 本檔內部連結 | E7: #重劃區清單_含內頁連結!A1
A8: └ sheet | B8: 縣市索引_22縣市 | C8: #縣市索引_22縣市!A1 | D8: 本檔內部連結 | E8: #縣市索引_22縣市!A1
A9: └ sheet | B9: 檔案清單_網站目錄樹 | C9: #檔案清單_網站目錄樹!A1 | D9: 本檔內部連結 | E9: #檔案清單_網站目錄樹!A1
A10: └ sheet | B10: 改前快照對照 | C10: #改前快照對照!A1 | D10: 本檔內部連結 | E10: #改前快照對照!A1
A11: └ sheet | B11: 研究說明 | C11: #研究說明!A1 | D11: 本檔內部連結 | E11: #研究說明!A1
A12: 既有檔案 | B12: 台灣22縣市重劃區_全站資料庫.xlsx | C12: 台灣22縣市重劃區_全站資料庫.xlsx | D12: 15 sheets | E12: 台灣22縣市重劃區_全站資料庫.xlsx
A13: └ sheet | B13: TOC | C13: (既有檔案內)
A14: └ sheet | B14: 規格書 | C14: (既有檔案內)
A15: └ sheet | B15: 指令與產出清單 | C15: (既有檔案內)
A16: └ sheet | B16: 網站參數 | C16: (既有檔案內)
A17: └ sheet | B17: 檔案清單 | C17: (既有檔案內)
A18: └ sheet | B18: 參數表 | C18: (既有檔案內)
A19: └ sheet | B19: UI元件與參數表 | C19: (既有檔案內)
A20: └ sheet | B20: 全站重劃區清單 | C20: (既有檔案內)
A21: └ sheet | B21: 縣市索引 | C21: (既有檔案內)
A22: └ sheet | B22: 缺圖清單 | C22: (既有檔案內)
A23: └ sheet | B23: 更新SOP | C23: (既有檔案內)
A24: └ sheet | B24: todolist | C24: (既有檔案內)
... A27: └ sheet | B27: 研究說明與覆蓋率 | C27: (既有檔案內)
A28: 既有檔案 | B28: 台灣22縣市重劃區_全站資料庫_改前快照_20261017.xlsx | C28: 台灣22縣市重劃區_全站資料庫_改前快照_20261017.xlsx | D28: 12 sheets | E28: 台灣22縣市重劃區_全站資料庫_改前快照_20261017.xlsx
A29: └ sheet | B29: TOC | C29: (既有檔案內)
A30: └ sheet | B30: 規格書 | C30: (既有檔案內)
A31: └ sheet | B31: 指令與產出清單 | C31: (既有檔案內)
A32: └ sheet | B32: 網站參數 | C32: (既有檔案內)
A33: └ sheet | B33: 檔案清單 | C33: (既有檔案內)
A34: └ sheet | B34: 參數表 | C34: (既有檔案內)
A35: └ sheet | B35: UI元件與參數表 | C35: (既有檔案內)
A36: └ sheet | B36: 全站重劃區清單 | C36: (既有檔案內)
A37: └ sheet | B37: 縣市索引 | C37: (既有檔案內)
A38: └ sheet | B38: 缺圖清單 | C38: (既有檔案內)
A39: └ sheet | B39: 更新SOP | C39: (既有檔案內)
A40: └ sheet | B40: todolist | C40: (既有檔案內)
A41: 既有檔案 | B41: 台灣22縣市重劃區_全站資料庫_整合版.xlsx | C41: 台灣22縣市重劃區_全站資料庫_整合版.xlsx | D41: 18 sheets | E41: 台灣22縣市重劃區_全站資料庫_整合版.xlsx
A42: └ sheet | B42: TOC | C42: (既有檔案內)
...

Sheet 主庫_重劃區146區
A1: seq | B1: 縣市 | C1: code | D1: slug | E1: region | F1: type | G1: type_file | H1: zone | I1: research_status | J1: notes | K1: 建案數
A2: 1 | B2: 臺北市 | C2: A21001 | D2: taipei | E2: 六大直轄市 | F2: 公辦市地重劃 | G2: public-urban-land-readjustment.html | H2: 南港公辦重劃 | I2: researched | J2: 對應南港三期公辦市地重劃（南港軟體園區三期周邊、三重路/向揚路一帶）。建案落區判斷：L3市場列表（樂居、PLEX、5168）以地址（三重路39號衡岄、成功路一段遠雄宜進、松河街東方大境）對照重劃區地籍大致範圍；精確邊界仍須以臺北市地政局重劃前後地號對照表（L2/L1）套繪GIS確認。遠雄宜進I-CITY位於成功路一段，介於南港三期重劃與南港車站特定專用區之間，是否完全落入重劃區內建議後續以L2邊界複核。 | K2: =COUNTIFS(建案總表_642案!$C$2:$C$643,$C2)
A3: 2 | B3: 臺北市 | C3: A21001 | D3: taipei | E3: 六大直轄市 | F3: 公辦市地重劃 | G3: public-urban-land-readjustment.html | H3: 內湖小型公辦重劃 | I3: researched | J3: 對應內湖葫洲/成功路五段一帶之小型公辦重劃（591實價登錄標註為「第四期重劃區」、永慶標註為「葫洲捷運二期重劃區」）。建案落區判斷：L3市場物件地址（成功路五段45巷、成功路五段450巷、成功路五段）與重劃區標註一致；惟內湖此區並非單一大型公辦重劃案，而是零散多期重劃，精確邊界與是否為「公辦」仍須查臺北市地政局重劃前後地號對照表（L1）確認，部分社區可能屬自辦或區段徵收周邊。 | K3: =COUNTIFS(建案總表_642案!$C$2:$C$643,$C3)
A4: 3 | B4: 臺北市 | C4: A21001 | D4: taipei | E4: 六大直轄市 | F4: 自辦市地重劃 | G4: private-urban-land-readjustment.html | H4: 零星小型自辦案 | I4: no_named_zone | J4: 本筆為佔位型案名，對應臺北市零星分布之小型自辦市地重劃（無單一連續範圍、無正式區名）。經檢索政府資料開放平臺「臺北市自辦市地重劃成果」與Google，臺北市自辦重劃規模普遍極小且分散，並未形成可供單獨列舉之住宅社區群，亦無市場網站以「自辦重劃區」為單位整理建案。故 builds 留空；後續若需補充，應以地政局自辦重劃成果清單逐案套繪GIS後再列舉。 | K4: =COUNTIFS(建案總表_642案!$C$2:$C$643,$C4)
A5: 4 | B5: 臺北市 | C5: A21001 | D5: taipei | E5: 六大直轄市 | F5: 都市更新 | G5: urban-renewal.html | H5: 西門公辦都更 | I5: researched | J5: 對應西門町（萬華區/中正區西門商圈）一帶之公辦/聯辦都市更新案。建案落區判斷：財團法人都市更新研究發展基金會官網（ur.org.tw）刊載西門町再更新相關案例（中華大樓案、福星段二小段576地號漢口街案），地址位於西門商圈核心。數字欄位（戶數/坪數/單價/推出年）在基金會新聞稿中未載明，故留空；精確規格須查臺北市都市更新處事業計畫核定書（L1）或後續實價登錄。 | K5: =COUNTIFS(建案總表_642案!$C$2:$C$643,$C5)
A6: 5 | B6: 臺北市 | C6: A21001 | D6: taipei | E6: 六大直轄市 | F6: 都市更新 | G6: urban-renewal.html | H6: 南港公辦都更 | I6: researched | J6: 對應南港區公辦都市更新（含台鐵南港調車場、南港機廠、玉成段、台電CR-1等公有/公辦更新單元）。建案落區判斷：ur.org.tw與臺北市住宅及都市更新中心（thurc.org.taipei）官方資料載明位置（市民大道七段/忠孝東路七段/南港段），均位於南港區東側公辦都算廊帶。南港調車場主體為商辦/會展/交通複合開發，住宅比例低；南港機廠社宅為社會住宅（非市場銷售）；玉成段案2026年才招商成功，尚未進入銷售階段，故價格欄位留空。 | K6: =COUNTIFS(建案總表_642案!$C$2:$C$643,$C6)
A7: 6 | B7: 臺北市 | C7: A21001 | D7: taipei | E7: 六大直轄市 | F7: 都市更新 | G7: urban-renewal.html | H7: 萬華公辦都更 | I7: researched | J7: 對應萬華區公辦都更/公有資產活化轉社會住宅案。建案落區判斷：國家住宅及都市更新中心官方網站（socialhousing.tw）與內政部國土署新聞稿載明地址為萬華區環河南路二段280巷6弄21、23號（華江國小旁，前身為西區憲兵隊、台糖停車場），A/B棟地上13及14層。本案為中央社會住宅（只租不售），故無市場單價；其餘萬華區民間都更案（如店面/透天更新）未列入，因不符「公辦都更」範圍。 | K7: =COUNTIFS(建案總表_642案!$C$2:$C$643,$C7)
A8: 7 | B8: 新北市 | C8: A21002 | D8: new-taipei | E8: 六大直轄市 | F8: 公辦市地重劃 | G8: public-urban-land-readjustment.html | H8: 塭仔圳重劃 | I8: researched | J8: 新、泰塭仔圳市地重劃橫跨新莊、泰山，面積約397公頃，分一、二區。以上個案由591新建案/5168實價登錄/MYDAChi之「塭仔圳重劃區」生活圈標籤及泰山區中環路二段、莊泰路、莊田路地址判定落在區內。重劃仍在開發中，抵費地標售與社宅(新莊塭仔圳青年社宅920戶)陸續推進，完整個案數待後續市場揭露。百達莊園實際座落新泰自辦重劃區、緊鄰塭仔圳，市場頁常以「塭仔圳重劃區」生活圈標示。 | K8: =COUNTIFS(建案總表_642案!$C$2:$C$643,$C8)
A9: 8 | B9: 新北市 | C9: A21002 | D9: new-taipei | E9: 六大直轄市 | F9: 公辦市地重劃 | G9: public-urban-land-readjustment.html | H9: 土城暫緩發展區重劃 | I9: researched | J9: 新北市地政局公辦市地重劃專頁確認本區範圍：東以青雲路、西以學府路東側、南以金城路及明德路北側、北以工五(大同公司)及文高(海山高工)為界(https://www.land.ntpc.gov.tw/cp.aspx?n=8806)。查591/樂居/新聞，本區仍處重劃開發與土地整頓階段，尚無明確以「暫緩發展區重劃」標榜之集合住宅個案列表；區域內多為都更案(沛陂段工業區、大巒段、樂利段)與土城司法園區/行政園區公開開發，非一般住宅预售個案，故builds暫留空。 | K9: =COUNTIFS(建案總表_642案!$C$2:$C$643,$C9)
A10: 9 | B10: 新北市 | C10: A21002 | D10: new-taipei | E10: 六大直轄市 | F10: 公辦市地重劃 | G10: public-urban-land-readjustment.html | H10: 板橋浮洲重劃 | I10: researched | J10: 浮洲地區以浮洲合宜住宅(日勝生活科技興建，A2/A3/A6三大區)為指標大型社區，位板橋浮洲樂群路/學府路一帶。新北市都更處115年9月再公告「板橋(浮洲地區)都市更新地區及都市更新計畫案」，後續都更個案陸續展開。戶數/坪數因合宜住宅分區多棟、公開頁未給單一社區總數，故留空。 | K10: =COUNTIFS(建案總表_642案!$C$2:$C$643,$C10)
A11: 10 | B11: 新北市 | C11: A21002 | D11: new-taipei | E11: 六大直轄市 | F11: 公辦市地重劃 | G11: public-urban-land-readjustment.html | H11: 其他中小型公辦案 | I11: no_named_zone | J11: 本筆為佔位型案名，非單一特定重劃區。新北市地政局公辦市地重劃已完成區尚含三重二重埔、三重重陽橋引道附近地區、二重疏洪道兩側等(部分另列seq16)，無單一可對應之住宅個案列表，故builds留空。 | K11: =COUNTIFS(建案總表_642案!$C$2:$C$643,$C11)
A12: 11 | B12: 新北市 | C12: A21002 | D12: new-taipei | E12: 六大直轄市 | F12: 自辦市地重劃 | G12: private-urban-land-readjustment.html | H12: 三峽自辦重劃群 | I12: researched | J12: 三峽自辦重劃群為佔位型案名。三峽區實際最大住宅開發為「臺北大學社區特定區(北大特區)」，以區段徵收方式自民國86年開發，橫跨三峽、樹林，上述個案皆為樂居/實價登錄收錄之北大特區內指標社區(housefeel 2026/09整理)。純自辦市地重劃個案在三峽市場列表中未見獨立成區之大型住宅群，故以北大特區可查證個案代表三峽主要住宅重劃聚落，並在此說明類型差異。 | K12: =COUNTIFS(建案總表_642案!$C$2:$C$643,$C12)
A13: 12 | B13: 新北市 | C13: A21002 | D13: new-taipei | E13: 六大直轄市 | F13: 自辦市地重劃 | G13: private-urban-land-readjustment.html | H13: 中和自辦重劃 | I13: researched | J13: 新北市地政局有「中和區大洋自辦市地重劃區」專頁(https://www.land.ntpc.gov.tw/cp.aspx?n=10659)，為中和區少見之自辦市地重劃。查591/樂居/新聞，該大洋自辦重劃區目前以土地重劃開發為主，尚無以該重劃區標榜之集合住宅個案在市場列表明確揭露名稱、戶數與坪數，故builds暫留空。 | K13: =COUNTIFS(建案總表_642案!$C$2:$C$643,$C13)
... A147: 146 | B147: 連江縣 | C147: A21020 | D147: lienchiang | E147: 離島地區 | F147: 區段徵收 | G147: zone-expropriation.html | H147: 僅公共建設類 | I147: no_data | J147: 連江縣無住宅區導向之區段徵收案；建設以港灣、軍事、公共設施為主。故 builds 留空。 | K147: =COUNTIFS(建案總表_642案!$C$2:$C$643,$C147)

Sheet 建案總表_642案
A1: seq | B1: 縣市 | C1: code | D1: slug | E1: zone | F1: type | G1: 建案名稱 | H1: 建商 | I1: 戶數 | J1: 坪數區間 | K1: 單價區間 | L1: 年份 | M1: 狀態 | N1: 來源等級 | O1: 來源網址
A2: 1 | B2: 臺北市 | C2: A21001 | D2: taipei | E2: 南港公辦重劃 | F2: 公辦市地重劃 | G2: 衡岄 | H2: 大陸建設 | J2: 25-42坪 | K2: 150-165萬/坪 | L2: 2025 | M2: 預售 | N2: L3 | O2: https://www.leju.com.tw/community/Lfbd151940d8acd；https://www.continental-propertydevelopment.com/zh/portfolio/residential/GARDEN-OF-HAPPINESS/
A3: 2 | B3: 臺北市 | C3: A21001 | D3: taipei | E3: 南港公辦重劃 | F3: 公辦市地重劃 | G3: 遠雄宜進I-CITY | H3: 遠雄建設 | I3: 98戶 | J3: 90-125坪 | K3: 約72.7萬/坪 | M3: 已完工 | N3: L3 | O3: https://community.houseprice.tw/building/172037/
A4: 3 | B4: 臺北市 | C4: A21001 | D4: taipei | E4: 南港公辦重劃 | F4: 公辦市地重劃 | G4: 東方大境 | H4: 國賓大建設/雄域建設 | J4: 18-38坪 | L4: 2025 | M4: 預售 | N4: L3 | O4: https://www.plex.com.tw/projects/view/id/6804/page/2
A5: 4 | B5: 臺北市 | C5: A21001 | D5: taipei | E5: 內湖小型公辦重劃 | F5: 公辦市地重劃 | G5: 大氣天成 | I5: 21戶 | K5: 約69.6萬/坪 | M5: 已完工 | N5: L3 | O5: https://market.591.com.tw/5531?room=4
A6: 5 | B6: 臺北市 | C6: A21001 | D6: taipei | E6: 內湖小型公辦重劃 | F6: 公辦市地重劃 | G6: 富邦大衛營領袖區 | H6: 富邦建設 | L6: 2008 | M6: 已完工 | N6: L3 | O6: https://www.plex.com.tw/projects/view/id/6038
A7: 6 | B7: 臺北市 | C7: A21001 | D7: taipei | E7: 內湖小型公辦重劃 | F7: 公辦市地重劃 | G7: 麗景 | J7: 約30坪 | M7: 已完工 | N7: L3 | O7: https://community.yungching.com.tw/building/7906/sale-around
A8: 7 | B8: 臺北市 | C8: A21001 | D8: taipei | E8: 西門公辦都更 | F8: 都市更新 | G8: 中華大樓都更案（西門電影街） | H8: 國泰建經 | M8: 規劃中 | N8: L3 | O8: https://www.ur.org.tw/mynews/view/55
A9: 8 | B9: 臺北市 | C9: A21001 | D9: taipei | E9: 西門公辦都更 | F9: 都市更新 | G9: 福星段二小段576地號都更案（漢口街） | H9: 興洋建設 | M9: 已完銷/完工 | N9: L3 | O9: https://www.ur.org.tw/mynews/view/55
A10: 9 | B10: 臺北市 | C10: A21001 | D10: taipei | E10: 南港公辦都更 | F10: 都市更新 | G10: 南港調車場公辦都更案（東街廓） | H10: 南港國際一/二股份有限公司 | M10: 興建中 | N10: L3 | O10: https://www.ur.org.tw/plan/career_view/83；https://www.housefeel.com.tw/article/%E5%8D%97%E6%B8%AF%E9%83%BD%E6%9B%B4-%E5%8D%97%E6%B8%AF%E8%AA%BF%E8%BB%8A%E5%A0%B4-%E5%8D%97%E6%B8%AF%E8%AA%BF%E8%BB%8A%E5%A0%B4%E9%83%BD%E6%9B%B4/
A11: 10 | B11: 臺北市 | C11: A21001 | D11: taipei | E11: 南港公辦都更 | F11: 都市更新 | G11: 南港機廠社會住宅 | H11: 臺北市政府（大陸工程興建） | I11: 1442戶 | L11: 2024 | M11: 已完工 | N11: L1 | O11: https://rent.thurc.org.taipei/Rental/Site/nangangdepot1；https://www.continental-engineering.com/zh/featured-projects/nangang-depot-public-housing/
A12: 11 | B12: 臺北市 | C12: A21001 | D12: taipei | E12: 南港公辦都更 | F12: 都市更新 | G12: 玉成段一小段430地號公辦都更案 | H12: 國泰建設/三重置業地產（三井） | I12: 130戶（原） | L12: 2026 | M12: 招商成功/規劃中 | N12: L3 | O12: https://94m.com.tw/articles/c2ac38
A13: 12 | B13: 臺北市 | C13: A21001 | D13: taipei | E13: 南港公辦都更 | F13: 都市更新 | G13: 台電CR-1都更案 | H13: 台電 | M13: 規劃中 | N13: L3 | O13: https://www.housefeel.com.tw/article/%E5%8D%97%E6%B8%AF%E9%83%BD%E6%9B%B4-%E5%8F%B0%E9%9B%BBcr1-%E5%8F%B0%E7%81%A3%E9%9B%BB%E5%8A%9B%E5%85%AC%E5%8F%B8/
A14: 13 | B14: 臺北市 | C14: A21001 | D14: taipei | E14: 萬華公辦都更 | F14: 都市更新 | G14: 萬華安居社會住宅 | H14: 國家住宅及都市更新中心 | I14: 300戶 | J14: 13.8-39.03坪 | L14: 2025 | M14: 已完工 | N14: L1 | O14: https://www.socialhousing.tw/portal/FindGoodHouseBuilding；https://www.moi.gov.tw/News_Content.aspx?n=10&s=328553
A15: 14 | B15: 新北市 | C15: A21002 | D15: new-taipei | E15: 塭仔圳重劃 | F15: 公辦市地重劃 | G15: 百達莊園 | H15: 偉築建設 | I15: 328戶 | J15: 27-47坪 | K15: 63-66萬/坪 | L15: 2027 | M15: 預售 | N15: L3 | O15: https://newhouse.591.com.tw/140169
A16: 15 | B16: 新北市 | C16: A21002 | D16: new-taipei | E16: 塭仔圳重劃 | F16: 公辦市地重劃 | G16: 築滿滿 | H16: 璞元建設(璞園)/堃達土地開發 | I16: 392戶 | J16: 26-42坪 | M16: 銷售中 | N16: L3 | O16: https://www.mydachi.com.tw/reviewer/taishan_jmm/
A17: 16 | B17: 新北市 | C17: A21002 | D17: new-taipei | E17: 塭仔圳重劃 | F17: 公辦市地重劃 | G17: 宏國宏道豐滙 | H17: 宏國建設 | J17: 48坪 | M17: 交屋中 | N17: L3 | O17: https://community.houseprice.tw/building/140382/sell/
A18: 17 | B18: 新北市 | C18: A21002 | D18: new-taipei | E18: 塭仔圳重劃 | F18: 公辦市地重劃 | G18: 明日城御風 | K18: 52萬/坪 | M18: 已完工 | N18: L3 | O18: https://market.591.com.tw/11971?room=1
A19: 18 | B19: 新北市 | C19: A21002 | D19: new-taipei | E19: 板橋浮洲重劃 | F19: 公辦市地重劃 | G19: 日勝幸福站(浮洲合宜住宅) | H19: 日勝生活科技 | L19: 2014 | M19: 已完工 | N19: L3 | O19: http://www.perfectlife.com.tw/index
A20: 19 | B20: 新北市 | C20: A21002 | D20: new-taipei | E20: 板橋浮洲重劃 | F20: 公辦市地重劃 | G20: 浮洲合宜住宅(A2/A3/A6) | L20: 2014 | M20: 已完工 | N20: L3 | O20: https://www.twarchitect.org.tw/special/%E6%B5%AE%E6%B4%B2%E5%90%88%E5%AE%9C%E4%BD%8F%E5%AE%85%E5%86%8D%E6%8E%A2/
A21: 20 | B21: 新北市 | C21: A21002 | D21: new-taipei | E21: 三峽自辦重劃群 | F21: 自辦市地重劃 | G21: 遠雄耶魯 | H21: 遠雄建設 | I21: 1024戶 | K21: 46.51萬/坪 | M21: 已完工 | N21: L3 | O21: https://www.housefeel.com.tw/article/%E5%8C%97%E5%A4%A7%E7%89%B9%E5%8D%80-%E5%8C%97%E5%A4%A7-%E4%B8%89%E5%B3%BD-%E4%B8%89%E9%B6%AF%E7%B7%9A/
A22: 21 | B22: 新北市 | C22: A21002 | D22: new-taipei | E22: 三峽自辦重劃群 | F22: 自辦市地重劃 | G22: 遠雄大學劍橋 | H22: 遠雄建設 | I22: 824戶 | K22: 43.72萬/坪 | M22: 已完工 | N22: L3 | O22: https://www.housefeel.com.tw/article/%E5%8C%97%E5%A4%A7%E7%89%B9%E5%8D%80-%E5%8C%97%E5%A4%A7-%E4%B8%89%E5%B3%BD-%E4%B8%89%E9%B6%AF%E7%B7%9A/
A23: 22 | B23: 新北市 | C23: A21002 | D23: new-taipei | E23: 三峽自辦重劃群 | F23: 自辦市地重劃 | G23: 麗寶國際館 | H23: 麗寶建設 | I23: 431戶 | K23: 50.29萬/坪 | M23: 已完工 | N23: L3 | O23: https://www.housefeel.com.tw/article/%E5%8C%97%E5%A4%A7%E7%89%B9%E5%8D%80-%E5%8C%97%E5%A4%A7-%E4%B8%89%E5%B3%BD-%E4%B8%89%E9%B6%AF%E7%B7%9A/
A24: 23 | B24: 新北市 | C24: A21002 | D24: new-taipei | E24: 三峽自辦重劃群 | F24: 自辦市地重劃 | G24: 將捷MIT | H24: 將捷建設 | I24: 155戶 | J24: 26-52坪 | K24: 58.93萬/坪 | M24: 已完工 | N24: L3 | O24: https://www.housefeel.com.tw/article/%E5%8C%97%E5%A4%A7%E7%89%B9%E5%8D%80-%E5%8C%97%E5%A4%A7-%E4%B8%89%E5%B3%BD-%E4%B8%89%E9%B6%AF%E7%B7%9A/
A25: 24 | B25: 新北市 | C25: A21002 | D25: new-taipei | E25: 三峽自辦重劃群 | F25: 自辦市地重劃 | G25: 北大極 | I25: 89戶 | J25: 18-30坪 | K25: 68.57萬/坪 | M25: 交屋中 | N25: L3 | O25: https://www.housefeel.com.tw/article/%E5%8C%97%E5%A4%A7%E7%89%B9%E5%8D%80-%E5%8C%97%E5%A4%A7-%E4%B8%89%E5%B3%BD-%E4%B8%89%E9%B6%AF%E7%B7%9A/
A26: 25 | B26: 新北市 | C26: A21002 | D26: new-taipei | E26: 三峽自辦重劃群 | F26: 自辦市地重劃 | G26: 女王萬歲2 | I26: 41戶 | J26: 25-35坪 | K26: 65.63萬/坪 | M26: 交屋中 | N26: L3 | O26: https://www.housefeel.com.tw/article/%E5%8C%97%E5%A4%A7%E7%89%B9%E5%8D%80-%E5%8C%97%E5%A4%A7-%E4%B8%89%E5%B3%BD-%E4%B8%89%E9%B6%AF%E7%B7%9A/
A27: 26 | B27: 新北市 | C27: A21002 | D27: new-taipei | E27: 三峽自辦重劃群 | F27: 自辦市地重劃 | G27: 北大悠揚 | I27: 144戶 | J27: 23-37坪 | K27: 60.06萬/坪 | L27: 2030 | M27: 預售 | N27: L3 | O27: https://www.housefeel.com.tw/article/%E5%8C%97%E5%A4%A7%E7%89%B9%E5%8D%80-%E5%8C%97%E5%A4%A7-%E4%B8%89%E5%B3%BD-%E4%B8%89%E9%B6%AF%E7%B7%9A/
A28: 27 | B28: 新北市 | C28: A21002 | D28: new-taipei | E28: 三峽自辦重劃群 | F28: 自辦市地重劃 | G28: 將捷朗學 | H28: 將捷建設 | I28: 60戶 | J28: 20-38坪 | K28: 69.02萬/坪 | L28: 2029 | M28: 預售 | N28: L3 | O28: https://www.housefeel.com.tw/article/%E5%8C%97%E5%A4%A7%E7%89%B9%E5%8D%80-%E5%8C%97%E5%A4%A7-%E4%B8%89%E5%B3%BD-%E4%B8%89%E9%B6%AF%E7%B7%9A/
A29: 28 | B29: 新北市 | C29: A21002 | D29: new-taipei | E29: 林口新市鎮 | F29: 區段徵收 | G29: A8敦品/緯詮美學 | H29: 緯詮建設 | I29: 83戶 | K29: 53.98萬/坪 | M29: 已完工 | N29: L3 | O29: https://www.housefeel.com.tw/article/%E6%9E%97%E5%8F%A3%E6%96%B0%E5%B8%82%E9%8E%AE-a7-a8-a9-%E6%9E%97%E5%8F%A3%E9%87%8D%E5%8A%83%E5%8D%80/
A30: 29 | B30: 新北市 | C30: A21002 | D30: new-taipei | E30: 林口新市鎮 | F30: 區段徵收 | G30: 三禾雅堺 | I30: 27戶 | K30: 54.67萬/坪 | M30: 已完工 | N30: L3 | O30: https://www.housefeel.com.tw/article/%E6%9E%97%E5%8F%A3%E6%96%B0%E5%B8%82%E9%8E%AE-a7-a8-a9-%E6%9E%97%E5%8F%A3%E9%87%8D%E5%8A%83%E5%8D%80/
A31: 30 | B31: 新北市 | C31: A21002 | D31: new-taipei | E31: 林口新市鎮 | F31: 區段徵收 | G31: 藝學苑 | I31: 53戶 | K31: 42.35萬/坪 | M31: 已完工 | N31: L3 | O31: https://www.housefeel.com.tw/article/%E6%9E%97%E5%8F%A3%E6%96%B0%E5%B8%82%E9%8E%AE-a7-a8-a9-%E6%9E%97%E5%8F%A3%E9%87%8D%E5%8A%83%E5%8D%80/
A32: 31 | B32: 新北市 | C32: A21002 | D32: new-taipei | E32: 林口新市鎮 | F32: 區段徵收 | G32: 鴻越雲鼎 | H32: 鴻越建設 | I32: 41戶 | K32: 53.16萬/坪 | M32: 已完工 | N32: L3 | O32: https://www.housefeel.com.tw/article/%E6%9E%97%E5%8F%A3%E6%96%B0%E5%B8%82%E9%8E%AE-a7-a8-a9-%E6%9E%97%E5%8F%A3%E9%87%8D%E5%8A%83%E5%8D%80/
A33: 32 | B33: 新北市 | C33: A21002 | D33: new-taipei | E33: 林口新市鎮 | F33: 區段徵收 | G33: 合輝豐秀 | H33: 合輝建設 | I33: 75戶 | M33: 已完工 | N33: L3 | O33: https://www.housefeel.com.tw/article/%E6%9E%97%E5%8F%A3%E6%96%B0%E5%B8%82%E9%8E%AE-a7-a8-a9-%E6%9E%97%E5%8F%A3%E9%87%8D%E5%8A%83%E5%8D%80/
A34: 33 | B34: 新北市 | C34: A21002 | D34: new-taipei | E34: 林口新市鎮 | F34: 區段徵收 | G34: 福樺春天 | H34: 福樺建設 | I34: 343戶 | K34: 66.91萬/坪 | L34: 2030 | M34: 預售 | N34: L3 | O34: https://www.housefeel.com.tw/article/%E6%9E%97%E5%8F%A3%E6%96%B0%E5%B8%82%E9%8E%AE-a7-a8-a9-%E6%9E%97%E5%8F%A3%E9%87%8D%E5%8A%83%E5%8D%80/
A35: 34 | B35: 新北市 | C35: A21002 | D35: new-taipei | E35: 林口新市鎮 | F35: 區段徵收 | G35: 寶品極智3 | H35: 寶品建設 | I35: 12戶 | K35: 57.54萬/坪 | L35: 2026 | M35: 預售 | N35: L3 | O35: https://www.housefeel.com.tw/article/%E6%9E%97%E5%8F%A3%E6%96%B0%E5%B8%82%E9%8E%AE-a7-a8-a9-%E6%9E%97%E5%8F%A3%E9%87%8D%E5%8A%83%E5%8D%80/
A36: 35 | B36: 新北市 | C36: A21002 | D36: new-taipei | E36: 林口新市鎮 | F36: 區段徵收 | G36: 昇樺樂活 | H36: 昇樺建設 | I36: 58戶 | K36: 48.21萬/坪 | L36: 2026 | M36: 預售 | N36: L3 | O36: https://www.housefeel.com.tw/article/%E6%9E%97%E5%8F%A3%E6%96%B0%E5%B8%82%E9%8E%AE-a7-a8-a9-%E6%9E%97%E5%8F%A3%E9%87%8D%E5%8A%83%E5%8D%80/
A37: 36 | B37: 新北市 | C37: A21002 | D37: new-taipei | E37: 林口新市鎮 | F37: 區段徵收 | G37: 長堤天昀 | H37: 長堤建設 | I37: 232戶 | K37: 45.22萬/坪 | L37: 2029 | M37: 預售 | N37: L3 | O37: https://www.housefeel.com.tw/article/%E6%9E%97%E5%8F%A3%E6%96%B0%E5%B8%82%E9%8E%AE-a7-a8-a9-%E6%9E%97%E5%8F%A3%E9%87%8D%E5%8A%83%E5%8D%80/
A38: 37 | B38: 新北市 | C38: A21002 | D38: new-taipei | E38: 林口新市鎮 | F38: 區段徵收 | G38: 亞昕晴空樹 | H38: 亞昕建設 | I38: 315戶 | K38: 64.51萬/坪 | M38: 已完工 | N38: L3 | O38: https://www.housefeel.com.tw/article/%E6%9E%97%E5%8F%A3%E6%96%B0%E5%B8%82%E9%8E%AE-a7-a8-a9-%E6%9E%97%E5%8F%A3%E9%87%8D%E5%8A%83%E5%8D%80/
A39: 38 | B39: 新北市 | C39: A21002 | D39: new-taipei | E39: 林口新市鎮 | F39: 區段徵收 | G39: 亞昕星空樹 | H39: 亞昕建設 | I39: 193戶 | K39: 63.44萬/坪 | M39: 已完工 | N39: L3 | O39: https://www.housefeel.com.tw/article/%E6%9E%97%E5%8F%A3%E6%96%B0%E5%B8%82%E9%8E%AE-a7-a8-a9-%E6%9E%97%E5%8F%A3%E9%87%8D%E5%8A%83%E5%8D%80/
A40: 39 | B40: 新北市 | C40: A21002 | D40: new-taipei | E40: 林口新市鎮 | F40: 區段徵收 | G40: 玄泰V PARK | H40: 玄泰建設 | I40: 57戶 | K40: 62.21萬/坪 | M40: 已完工 | N40: L3 | O40: https://www.housefeel.com.tw/article/%E6%9E%97%E5%8F%A3%E6%96%B0%E5%B8%82%E9%8E%AE-a7-a8-a9-%E6%9E%97%E5%8F%A3%E9%87%8D%E5%8A%83%E5%8D%80/
...

Sheet 重劃區清單_含內頁連結
A1: seq | B1: 縣市 | C1: slug | D1: region | E1: type | F1: type_file | G1: zone | H1: research_status | I1: 建案數 | J1: 內頁目標檔名 | K1: 產出狀態 | L1: 相對路徑連結
A2: 1 | B2: 臺北市 | C2: taipei | D2: 六大直轄市 | E2: 公辦市地重劃 | F2: public-urban-land-readjustment.html | G2: 南港公辦重劃 | H2: researched | I2: =COUNTIFS(建案總表_642案!$E$2:$E$643,$G2) | J2: taipei/南港公辦重劃.html | K2: 已存在 | L2: taipei/南港公辦重劃.html
A3: 2 | B3: 臺北市 | C3: taipei | D3: 六大直轄市 | E3: 公辦市地重劃 | F3: public-urban-land-readjustment.html | G3: 內湖小型公辦重劃 | H3: researched | I3: =COUNTIFS(建案總表_642案!$E$2:$E$643,$G3) | J3: taipei/內湖小型公辦重劃.html | K3: 已存在 | L3: taipei/內湖小型公辦重劃.html
A4: 3 | B4: 臺北市 | C4: taipei | D4: 六大直轄市 | E4: 自辦市地重劃 | F4: private-urban-land-readjustment.html | G4: 零星小型自辦案 | H4: no_named_zone | I4: =COUNTIFS(建案總表_642案!$E$2:$E$643,$G4) | J4: taipei/零星小型自辦案.html | K4: 已存在 | L4: taipei/零星小型自辦案.html
A5: 4 | B5: 臺北市 | C5: taipei | D5: 六大直轄市 | E5: 都市更新 | F5: urban-renewal.html | G5: 西門公辦都更 | H5: researched | I5: =COUNTIFS(建案總表_642案!$E$2:$E$643,$G5) | J5: taipei/西門公辦都更.html | K5: 已存在 | L5: taipei/西門公辦都更.html
A6: 5 | B6: 臺北市 | C6: taipei | D6: 六大直轄市 | E6: 都市更新 | F6: urban-renewal.html | G6: 南港公辦都更 | H6: researched | I6: =COUNTIFS(建案總表_642案!$E$2:$E$643,$G6) | J6: taipei/南港公辦都更.html | K6: 已存在 | L6: taipei/南港公辦都更.html
A7: 6 | B7: 臺北市 | C7: taipei | D7: 六大直轄市 | E7: 都市更新 | F7: urban-renewal.html | G7: 萬華公辦都更 | H7: researched | I7: =COUNTIFS(建案總表_642案!$E$2:$E$643,$G7) | J7: taipei/萬華公辦都更.html | K7: 已存在 | L7: taipei/萬華公辦都更.html
A8: 7 | B8: 新北市 | C8: new-taipei | D8: 六大直轄市 | E8: 公辦市地重劃 | F8: public-urban-land-readjustment.html | G8: 塭仔圳重劃 | H8: researched | I8: =COUNTIFS(建案總表_642案!$E$2:$E$643,$G8) | J8: new-taipei/塭仔圳重劃.html | K8: 已存在 | L8: new-taipei/塭仔圳重劃.html
A9: 8 | B9: 新北市 | C9: new-taipei | D9: 六大直轄市 | E9: 公辦市地重劃 | F9: public-urban-land-readjustment.html | G9: 土城暫緩發展區重劃 | H9: researched | I9: =COUNTIFS(建案總表_642案!$E$2:$E$643,$G9) | J9: new-taipei/土城暫緩發展區重劃.html | K9: 已存在 | L9: new-taipei/土城暫緩發展區重劃.html
A10: 9 | B10: 新北市 | C10: new-taipei | D10: 六大直轄市 | E10: 公辦市地重劃 | F10: public-urban-land-readjustment.html | G10: 板橋浮洲重劃 | H10: researched | I10: =COUNTIFS(建案總表_642案!$E$2:$E$643,$G10) | J10: new-taipei/板橋浮洲重劃.html | K10: 已存在 | L10: new-taipei/板橋浮洲重劃.html
A11: 10 | B11: 新北市 | C11: new-taipei | D11: 六大直轄市 | E11: 公辦市地重劃 | F11: public-urban-land-readjustment.html | G11: 其他中小型公辦案 | H11: no_named_zone | I11: =COUNTIFS(建案總表_642案!$E$2:$E$643,$G11) | J11: new-taipei/其他中小型公辦案.html | K11: 已存在 | L11: new-taipei/其他中小型公辦案.html
A12: 11 | B12: 新北市 | C12: new-taipei | D12: 六大直轄市 | E12: 自辦市地重劃 | F12: private-urban-land-readjustment.html | G12: 三峽自辦重劃群 | H12: researched | I12: =COUNTIFS(建案總表_642案!$E$2:$E$643,$G12) | J12: new-taipei/三峽自辦重劃群.html | K12: 已存在 | L12: new-taipei/三峽自辦重劃群.html
A13: 12 | B13: 新北市 | C13: new-taipei | D13: 六大直轄市 | E13: 自辦市地重劃 | F13: private-urban-land-readjustment.html | G13: 中和自辦重劃 | H13: researched | I13: =COUNTIFS(建案總表_642案!$E$2:$E$643,$G13) | J13: new-taipei/中和自辦重劃.html | K13: 已存在 | L13: new-taipei/中和自辦重劃.html
... A147: 146 | B147: 連江縣 | C147: lienchiang | D147: 離島地區 | E147: 區段徵收 | F147: zone-expropriation.html | G147: 僅公共建設類 | H147: no_data | I147: =COUNTIFS(建案總表_642案!$E$2:$E$643,$G147) | J147: lienchiang/僅公共建設類.html | K147: 已存在 | L147: lienchiang/僅公共建設類.html

Sheet 縣市索引_22縣市
A1: 縣市 | B1: slug | C1: region | D1: 重劃區數 | E1: 建案數 | F1: index.html | G1: 公辦市地重劃頁 | H1: 自辦市地重劃頁 | I1: 區段徵收頁 | J1: 都市更新頁 | K1: 百科頁
A2: 臺北市 | B2: taipei | C2: 六大直轄市 | D2: =COUNTIF(主庫_重劃區146區!$B$2:$B$147,$A2) | E2: =COUNTIFS(建案總表_642案!$B$2:$B$643,$A2) | F2: taipei/index.html | G2: taipei/public-urban-land-readjustment.html | H2: taipei/private-urban-land-readjustment.html | I2: taipei/zone-expropriation.html | J2: taipei/urban-renewal.html | K2: taipei/百科-臺北市重劃區與建案.html
A3: 新北市 | B3: new-taipei | C3: 六大直轄市 | D3: =COUNTIF(主庫_重劃區146區!$B$2:$B$147,$A3) | E3: =COUNTIFS(建案總表_642案!$B$2:$B$643,$A3) | F3: new-taipei/index.html | G3: new-taipei/public-urban-land-readjustment.html | H3: new-taipei/private-urban-land-readjustment.html | I3: new-taipei/zone-expropriation.html | J3: new-taipei/urban-renewal.html | K3: new-taipei/新北市重劃區與建案.html
A4: 桃園市 | B4: taoyuan | C4: 六大直轄市 | D4: =COUNTIF(主庫_重劃區146區!$B$2:$B$147,$A4) | E4: =COUNTIFS(建案總表_642案!$B$2:$B$643,$A4) | F4: taoyuan/index.html | G4: taoyuan/public-urban-land-readjustment.html | H4: taoyuan/private-urban-land-readjustment.html | I4: taoyuan/zone-expropriation.html | J4: taoyuan/urban-renewal.html | K4: taoyuan/encyclopedia.html
A5: 臺中市 | B5: taichung | C5: 六大直轄市 | D5: =COUNTIF(主庫_重劃區146區!$B$2:$B$147,$A5) | E5: =COUNTIFS(建案總表_642案!$B$2:$B$643,$A5) | F5: taichung/index.html | G5: taichung/public-urban-land-readjustment.html | H5: taichung/private-urban-land-readjustment.html | I5: taichung/zone-expropriation.html | J5: taichung/urban-renewal.html | K5: taichung/百科-臺中市重劃區與建案.html
A6: 臺南市 | B6: tainan | C6: 六大直轄市 | D6: =COUNTIF(主庫_重劃區146區!$B$2:$B$147,$A6) | E6: =COUNTIFS(建案總表_642案!$B$2:$B$643,$A6) | F6: tainan/index.html | G6: tainan/public-urban-land-readjustment.html | H6: tainan/private-urban-land-readjustment.html | I6: tainan/zone-expropriation.html | J6: tainan/urban-renewal.html | K6: tainan/百科-臺南市重劃區與建案.html
A7: 高雄市 | B7: kaohsiung | C7: 六大直轄市 | D7: =COUNTIF(主庫_重劃區146區!$B$2:$B$147,$A7) | E7: =COUNTIFS(建案總表_642案!$B$2:$B$643,$A7) | F7: kaohsiung/index.html | G7: kaohsiung/public-urban-land-readjustment.html | H7: kaohsiung/private-urban-land-readjustment.html | I7: kaohsiung/zone-expropriation.html | J7: kaohsiung/urban-renewal.html | K7: kaohsiung/百科-高雄市重劃區與建案.html
A8: 基隆市 | B8: keelung | C8: 北部地區 | D8: =COUNTIF(主庫_重劃區146區!$B$2:$B$147,$A8) | E8: =COUNTIFS(建案總表_642案!$B$2:$B$643,$A8) | F8: keelung/index.html | G8: keelung/public-urban-land-readjustment.html | H8: keelung/private-urban-land-readjustment.html | I8: keelung/zone-expropriation.html | J8: keelung/urban-renewal.html | K8: keelung/百科-基隆市重劃區與建案.html
A9: 新竹市 | B9: hsinchu-city | C9: 北部地區 | D9: =COUNTIF(主庫_重劃區146區!$B$2:$B$147,$A9) | E9: =COUNTIFS(建案總表_642案!$B$2:$B$643,$A9) | F9: hsinchu-city/index.html | G9: hsinchu-city/public-urban-land-readjustment.html | H9: hsinchu-city/private-urban-land-readjustment.html | I9: hsinchu-city/zone-expropriation.html | J9: hsinchu-city/urban-renewal.html | K9: hsinchu-city/百科-新竹市重劃區與建案.html
A10: 新竹縣 | B10: hsinchu-county | C10: 北部地區 | D10: =COUNTIF(主庫_重劃區146區!$B$2:$B$147,$A10) | E10: =COUNTIFS(建案總表_642案!$B$2:$B$643,$A10) | F10: hsinchu-county/index.html | G10: hsinchu-county/public-urban-land-readjustment.html | H10: hsinchu-county/private-urban-land-readjustment.html | I10: hsinchu-county/zone-expropriation.html | J10: hsinchu-county/urban-renewal.html | K10: hsinchu-county/百科-新竹縣重劃區與建案.html
A11: 苗栗縣 | B11: miaoli | C11: 北部地區 | D11: =COUNTIF(主庫_重劃區146區!$B$2:$B$147,$A11) | E11: =COUNTIFS(建案總表_642案!$B$2:$B$643,$A11) | F11: miaoli/index.html | G11: miaoli/public-urban-land-readjustment.html | H11: miaoli/private-urban-land-readjustment.html | I11: miaoli/zone-expropriation.html | J11: miaoli/urban-renewal.html | K11: miaoli/百科-苗栗縣重劃區與建案.html
A12: 宜蘭縣 | B12: yilan | C12: 北部地區 | D12: =COUNTIF(主庫_重劃區146區!$B$2:$B$147,$A12) | E12: =COUNTIFS(建案總表_642案!$B$2:$B$643,$A12) | F12: yilan/index.html | G12: yilan/public-urban-land-readjustment.html | H12: yilan/private-urban-land-readjustment.html | I12: yilan/zone-expropriation.html | J12: yilan/urban-renewal.html | K12: yilan/百科-宜蘭縣重劃區與建案.html
A13: 彰化縣 | B13: changhua | C13: 中部地區 | D13: =COUNTIF(主庫_重劃區146區!$B$2:$B$147,$A13) | E13: =COUNTIFS(建案總表_642案!$B$2:$B$643,$A13) | F13: changhua/index.html | G13: changhua/public-urban-land-readjustment.html | H13: changhua/private-urban-land-readjustment.html | I13: changhua/zone-expropriation.html | J13: changhua/urban-renewal.html | K13: changhua/百科-彰化縣重劃區與建案.html
... A23: 連江縣 | B23: lienchiang | C23: 離島地區 | D23: =COUNTIF(主庫_重劃區146區!$B$2:$B$147,$A23) | E23: =COUNTIFS(建案總表_642案!$B$2:$B$643,$A23) | F23: lienchiang/index.html | G23: lienchiang/public-urban-land-readjustment.html | H23: lienchiang/private-urban-land-readjustment.html | I23: lienchiang/zone-expropriation.html | J23: lienchiang/urban-renewal.html | K23: lienchiang/百科-連江縣重劃區與建案.html

Sheet 檔案清單_網站目錄樹
A1: 分類 | B1: 相對路徑 | C1: 檔名 | D1: 狀態 | E1: 連結
A2: ①根目錄入口頁 | B2: index.html | C2: index.html | D2: 已存在 | E2: index.html
A3: ①根目錄入口頁 | B3: toc.html | C3: toc.html | D3: 已存在 | E3: toc.html
A4: ①根目錄入口頁 | B4: 台灣22縣市重劃區_整合導覽入口.html | C4: 台灣22縣市重劃區_整合導覽入口.html | D4: 已存在 | E4: 台灣22縣市重劃區_整合導覽入口.html
A5: ①根目錄入口頁 | B5: 台灣22縣市重劃區總目錄-.html | C5: 台灣22縣市重劃區總目錄-.html | D5: 已存在 | E5: 台灣22縣市重劃區總目錄-.html
A6: ①根目錄入口頁 | B6: 台灣22縣市重劃區總目錄.html | C6: 台灣22縣市重劃區總目錄.html | D6: 已存在 | E6: 台灣22縣市重劃區總目錄.html
A7: ①根目錄入口頁 | B7: 臺中市重劃區全目錄-.html | C7: 臺中市重劃區全目錄-.html | D7: 已存在 | E7: 臺中市重劃區全目錄-.html
A8: ①根目錄入口頁 | B8: 臺中市重劃區全目錄.html | C8: 臺中市重劃區全目錄.html | D8: 已存在 | E8: 臺中市重劃區全目錄.html
A9: ①根目錄入口頁 | B9: 臺中市重劃區買房實戰指南-.html | C9: 臺中市重劃區買房實戰指南-.html | D9: 已存在 | E9: 臺中市重劃區買房實戰指南-.html
A10: ①根目錄入口頁 | B10: 臺中市重劃區買房實戰指南.html | C10: 臺中市重劃區買房實戰指南.html | D10: 已存在 | E10: 臺中市重劃區買房實戰指南.html
A11: ②縣市內頁 | B11: taipei/index.html | C11: index.html | D11: 已存在 | E11: taipei/index.html
A12: ②縣市內頁 | B12: taipei/public-urban-land-readjustment.html | C12: public-urban-land-readjustment.html | D12: 已存在 | E12: taipei/public-urban-land-readjustment.html
... A145: ④Excel總庫 | B145: 台灣22縣市重劃區_全站資料庫_整合版.xlsx | C145: 台灣22縣市重劃區_全站資料庫_整合版.xlsx | D145: 已存在 | E145: 台灣22縣市重劃區_全站資料庫_整合版.xlsx
A146: ④Excel總庫 | B146: 台灣22縣市重劃區_全站資料庫_重建分類版.xlsx | C146: 台灣22縣市重劃區_全站資料庫_重建分類版.xlsx | D146: 待產出
A147: ⑤重劃區內頁 | B147: taipei/南港公辦重劃.html | C147: 南港公辦重劃.html | D147: 已存在 | E147: taipei/南港公辦重劃.html
A148: ⑤重劃區內頁 | B148: taipei/內湖小型公辦重劃.html | C148: 內湖小型公辦重劃.html | D148: 已存在 | E148: taipei/內湖小型公辦重劃.html
A149: ⑤重劃區內頁 | B149: taipei/零星小型自辦案.html | C149: 零星小型自辦案.html | D149: 待產出
A150: ⑤重劃區內頁 | B150: taipei/西門公辦都更.html | C150: 西門公辦都更.html | D150: 待產出
A151: ⑤重劃區內頁 | B151: taipei/南港公辦都更.html | C151: 南港公辦都更.html | D151: 待產出
A152: ⑤重劃區內頁 | B152: taipei/萬華公辦都更.html | C152: 萬華公辦都更.html | D152: 待產出
A153: ⑤重劃區內頁 | B153: new-taipei/塭仔圳重劃.html | C153: 塭仔圳重劃.html | D153: 待產出
A154: ⑤重劃區內頁 | B154: new-taipei/土城暫緩發展區重劃.html | C154: 土城暫緩發展區重劃.html | D154: 待產出
A155: ⑤重劃區內頁 | B155: new-taipei/板橋浮洲重劃.html | C155: 板橋浮洲重劃.html | D155: 待產出
A156: ⑤重劃區內頁 | B156: new-taipei/其他中小型公辦案.html | C156: 其他中小型公辦案.html | D156: 待產出
A157: ⑤重劃區內頁 | B157: new-taipei/三峽自辦重劃群.html | C157: 三峽自辦重劃群.html | D157: 待產出
A158: ⑤重劃區內頁 | B158: new-taipei/中和自辦重劃.html | C158: 中和自辦重劃.html | D158: 待產出
A159: ⑤重劃區內頁 | B159: new-taipei/樹林自辦重劃.html | C159: 樹林自辦重劃.html | D159: 待產出
A160: ⑤重劃區內頁 | B160: new-taipei/林口新市鎮.html | C160: 林口新市鎮.html | D160: 待產出
... A292: ⑤重劃區內頁 | B292: lienchiang/僅公共建設類.html | C292: 僅公共建設類.html | D292: 待產出

Sheet 改前快照對照
A1: 快照sheet名稱 | B1: 原用途概述 | C1: 重建版對應sheet | D1: 處置 | E1: 備註
A2: TOC | B2: 快照入口目錄，依分類列出各 sheet 用途說明 | C2: 連結TOC | D2: 內容已併入重建版 | E2: 重建版 TOC 改以超連結分區導覽
A3: 規格書 | B3: 使用說明及定義，頁籤顏色分類規範 | C3: 研究說明 | D3: 內容已併入重建版 | E3: 保留原檔供歷史參考
A4: 指令與產出清單 | B4: 建置指令與產出對照，含完成狀態 | C4: 研究說明 | D4: 保留原檔 | E4: 歷史建置紀錄，重建版不重複
A5: 網站參數 | B5: 全站參數/版型/命名/路徑設定 | C5: 研究說明 | D5: 保留原檔 | E5: 保留原檔供開發參考
A6: 檔案清單 | B6: 根目錄檔案與目錄結構說明 | C6: 檔案清單_網站目錄樹 | D6: 內容已併入重建版 | E6: 重建版擴充為五類分類完整樹狀
A7: 參數表 | B7: DATA 欄位定義與開發類型規則 | C7: 研究說明 | D7: 保留原檔 | E7: 保留原檔供開發參考
A8: UI元件與參數表 | B8: Megamenu 元件、CSS 選擇器與行為定義 | C8: 研究說明 | D8: 保留原檔 | E8: 前端技術參數，非資料庫範疇
A9: 全站重劃區清單 | B9: 146 列重劃區一覽（序/縣市/編碼/類型/案名/狀態） | C9: 主庫_重劃區146區 | D9: 內容已併入重建版 | E9: 重建版增加建案數公式與 notes 欄
A10: 縣市索引 | B10: 22 縣市一覽（序/縣市/slug/區域/編碼/目錄頁） | C10: 縣市索引_22縣市 | D10: 內容已併入重建版 | E10: 重建版增加 COUNTIF 統計與五檔連結
A11: 缺圖清單 | B11: 待補圖片項目清單（縣市/類型/優先序） | C11: (無直接對應) | D11: 保留原檔 | E11: 視覺素材待辦，非資料庫範疇
A12: 更新SOP | B12: 網站更新時須同步的 Excel 位置與流程 | C12: 研究說明 | D12: 保留原檔 | E12: 維運流程文件
A13: todolist | B13: 待辦事項（撰寫/資料/市場數據） | C13: (無直接對應) | D13: 保留原檔 | E13: 任務管理紀錄

Sheet 研究說明
A1: 項目 | B1: 內容
A2: 一、資料來源
A3: 主資料 JSON | B3: _builds_data/_merged_builds.json（146 重劃區、642 建案）
A4: 既有 Excel ① | B4: 台灣22縣市重劃區_全站資料庫.xlsx（15 sheets）
A5: 既有 Excel ② | B5: 台灣22縣市重劃區_全站資料庫_改前快照_20261017.xlsx（12 sheets）
A6: 既有 Excel ③ | B6: 台灣22縣市重劃區_全站資料庫_整合版.xlsx（18 sheets）
A8: 二、欄位定義
A9: seq | B9: 重劃區流水序號
A10: county / 縣市 | B10: 直轄市或縣市名（繁體）
A11: code | B11: 縣市行政區編碼（如 A21001）
A12: slug | B12: 縣目錄英文代碼（如 taipei）
A13: region | B13: 地理分區（六大直轄市/北部/中部/南部/東部/離島）
A14: type | B14: 開發類型：公辦市地重劃／自辦市地重劃／區段徵收／都市更新
A15: type_file | B15: 對應類型內頁檔名
A16: zone | B16: 重劃區名稱
A17: research_status | B17: 研究狀態：researched（已研究）／no_named_zone（無具名重劃區）／no_data（無資料）
A18: notes | B18: 備註與研究判斷說明
A19: builds[].name | B19: 建案名稱
A20: builds[].builder | B20: 建商
... A27: builds[].source_urls | B27: 來源網址列表
A29: 三、統計
A30: 重劃區總數 | B30: =COUNTA(主庫_重劃區146區!$H$2:$H$147)
A31: 建案總數 | B31: =COUNTA(建案總表_642案!$G$2:$G$643)
A32: 縣市數 | B32: 22
A33: 公辦市地重劃 | B33: =COUNTIF(主庫_重劃區146區!$F$2:$F$147,"公辦市地重劃")
A34: 自辦市地重劃 | B34: =COUNTIF(主庫_重劃區146區!$F$2:$F$147,"自辦市地重劃")
A35: 區段徵收 | B35: =COUNTIF(主庫_重劃區146區!$F$2:$F$147,"區段徵收")
A36: 都市更新 | B36: =COUNTIF(主庫_重劃區146區!$F$2:$F$147,"都市更新")
A37: researched | B37: =COUNTIF(主庫_重劃區146區!$I$2:$I$147,"researched")
A38: no_named_zone | B38: =COUNTIF(主庫_重劃區146區!$I$2:$I$147,"no_named_zone")
A39: no_data | B39: =COUNTIF(主庫_重劃區146區!$I$2:$I$147,"no_data")
A41: 四、方法與用語說明
A42: 產生日期 | B42: 2026-10-17
A43: 建置方式 | B43: openpyxl 從 _merged_builds.json 逐筆匯入，未臆造資料
A44: 公式策略 | B44: 建案數/重劃區數/類型分布均以 COUNTIF/COUNTIFS 公式驅動，非硬編碼
A45: 用語 | B45: 重劃區／建案／戶數／坪數／單價／區段徵收／都市更新（台灣慣用語）
A47: 五、已知限制
A48: 重劃區獨立內頁 | B48: 146 個目標檔名已預留（slug/zone.html），實體頁面由另一任務產出中；本表標註「待產出」
A49: 已存在內頁 | B49: 僅 2 個重劃區內頁已存在（taipei/南港公辦重劃、taipei/內湖小型公辦重劃），其餘 144 待產出
A50: 百科頁命名 | B50: 多數縣市為「百科-{縣市}重劃區與建案.html」，桃園市為 encyclopedia.html，新北市為「新北市重劃區與建案.html」
...
